<?xml version="1.0" encoding="UTF-8"?>
<testng-results ignored="1" total="2" passed="0" failed="1" skipped="0">
  <reporter-output>
  </reporter-output>
  <suite started-at="2023-05-02T10:20:47Z" name="Default suite" finished-at="2023-05-02T10:20:52Z" duration-ms="4728">
    <groups>
    </groups>
    <test started-at="2023-05-02T10:20:47Z" name="Default test" finished-at="2023-05-02T10:20:52Z" duration-ms="4728">
      <class name="testcases.LoginTest">
        <test-method is-config="true" signature="Setup()[pri:0, instance:testcases.LoginTest@1ab06251]" started-at="2023-05-02T10:20:47Z" name="Setup" finished-at="2023-05-02T10:20:48Z" duration-ms="842" status="PASS">
          <reporter-output>
          </reporter-output>
        </test-method> <!-- Setup -->
        <test-method is-config="true" signature="setup(java.lang.reflect.Method)[pri:0, instance:testcases.LoginTest@1ab06251]" started-at="2023-05-02T10:20:48Z" name="setup" finished-at="2023-05-02T10:20:51Z" duration-ms="3036" status="PASS">
          <params>
            <param index="0">
              <value>
                <![CDATA[public void testcases.LoginTest.negative(java.lang.reflect.Method) throws com.codoid.products.exception.FilloException]]>
              </value>
            </param>
          </params>
          <reporter-output>
          </reporter-output>
        </test-method> <!-- setup -->
        <test-method signature="negative(java.lang.reflect.Method)[pri:0, instance:testcases.LoginTest@1ab06251]" started-at="2023-05-02T10:20:51Z" name="negative" finished-at="2023-05-02T10:20:52Z" duration-ms="617" status="FAIL">
          <params>
            <param index="0">
              <value>
                <![CDATA[public void testcases.LoginTest.negative(java.lang.reflect.Method) throws com.codoid.products.exception.FilloException]]>
              </value>
            </param>
          </params>
          <exception class="java.lang.AssertionError">
            <message>
              <![CDATA[expected [Epic sadface: Username and password do not match any user in this service....] but found [Epic sadface: Username and password do not match any user in this service]]]>
            </message>
            <full-stacktrace>
              <![CDATA[java.lang.AssertionError: expected [Epic sadface: Username and password do not match any user in this service....] but found [Epic sadface: Username and password do not match any user in this service]
at org.testng.Assert.fail(Assert.java:96)
at org.testng.Assert.failNotEquals(Assert.java:776)
at org.testng.Assert.assertEqualsImpl(Assert.java:137)
at org.testng.Assert.assertEquals(Assert.java:118)
at org.testng.Assert.assertEquals(Assert.java:453)
at org.testng.Assert.assertEquals(Assert.java:463)
at testcases.LoginTest.negative(LoginTest.java:48)
at java.base/jdk.internal.reflect.NativeMethodAccessorImpl.invoke0(Native Method)
at java.base/jdk.internal.reflect.NativeMethodAccessorImpl.invoke(NativeMethodAccessorImpl.java:77)
at java.base/jdk.internal.reflect.DelegatingMethodAccessorImpl.invoke(DelegatingMethodAccessorImpl.java:43)
at java.base/java.lang.reflect.Method.invoke(Method.java:568)
at org.testng.internal.MethodInvocationHelper.invokeMethod(MethodInvocationHelper.java:124)
at org.testng.internal.Invoker.invokeMethod(Invoker.java:583)
at org.testng.internal.Invoker.invokeTestMethod(Invoker.java:719)
at org.testng.internal.Invoker.invokeTestMethods(Invoker.java:989)
at org.testng.internal.TestMethodWorker.invokeTestMethods(TestMethodWorker.java:125)
at org.testng.internal.TestMethodWorker.run(TestMethodWorker.java:109)
at org.testng.TestRunner.privateRun(TestRunner.java:648)
at org.testng.TestRunner.run(TestRunner.java:505)
at org.testng.SuiteRunner.runTest(SuiteRunner.java:455)
at org.testng.SuiteRunner.runSequentially(SuiteRunner.java:450)
at org.testng.SuiteRunner.privateRun(SuiteRunner.java:415)
at org.testng.SuiteRunner.run(SuiteRunner.java:364)
at org.testng.SuiteRunnerWorker.runSuite(SuiteRunnerWorker.java:52)
at org.testng.SuiteRunnerWorker.run(SuiteRunnerWorker.java:84)
at org.testng.TestNG.runSuitesSequentially(TestNG.java:1208)
at org.testng.TestNG.runSuitesLocally(TestNG.java:1137)
at org.testng.TestNG.runSuites(TestNG.java:1049)
at org.testng.TestNG.run(TestNG.java:1017)
at org.testng.remote.AbstractRemoteTestNG.run(AbstractRemoteTestNG.java:115)
at org.testng.remote.RemoteTestNG.initAndRun(RemoteTestNG.java:251)
at org.testng.remote.RemoteTestNG.main(RemoteTestNG.java:77)
]]>
            </full-stacktrace>
          </exception> <!-- java.lang.AssertionError -->
          <reporter-output>
          </reporter-output>
        </test-method> <!-- negative -->
        <test-method is-config="true" signature="TearDown()[pri:0, instance:testcases.LoginTest@1ab06251]" started-at="2023-05-02T10:20:52Z" name="TearDown" finished-at="2023-05-02T10:20:52Z" duration-ms="208" status="PASS">
          <reporter-output>
          </reporter-output>
        </test-method> <!-- TearDown -->
      </class> <!-- testcases.LoginTest -->
    </test> <!-- Default test -->
  </suite> <!-- Default suite -->
</testng-results>
